Workbook
Name _45°: Data!$I$124:$L$124
Name _50°: Data!$I$123:$L$123
Name _55°: Data!$I$122:$L$122
Name _60°: Data!$I$121:$L$121
Name _65°: Data!$I$120:$L$120
Name _70°: Data!$I$119:$L$119
Name _75°: Data!$I$118:$L$118
Name _90°: Data!$I$117:$L$117

Sheet Summary
A1: LOS Calculator for Three Design Options
A3: User to input data in RED. | B3: MDACC South Campus Garage 2
A4: Inputs | B4: Option 1 | C4: Option 2 | D4: Option 3 | G4: For Multi-User Group Garages Only (Hospital Mixed & University Mixed): Enter the percent mix of User Group below to lock in the peak load factor.
A5: Market Sector (Drop Down List) | B5: Research | E5: RAMPING | G5: Hospital Mixed: | J5: University Mixed:
A6: Number of Spaces (Whole Number Only) | B6: 1732 | G6: Visitor | H6: 0.25 | J6: Students | K6: 0
A7: Number of Levels (Whole Number Only) | B7: 7 | G7: Employees/Staff | H7: 0.25 | J7: Staff | K7: 0.5
A8: Ramp Type (Drop-Down List) | B8: Double Threaded Helix - 2 Way | G8: Outpatient | H8: 0.5 | J8: Faculty | K8: 0.5
A9: Ramp Slope (PERCENT) | B9: 4.86 | H9: =SUM(H6:H8) -> 1 | K9: =SUM(K6:K8) -> 1 | L9: Must add up to 100%
A10: Number of Turns to Last Space (Decimal) | B10: 3.5
A11: Number of Spaces Not Engaged by Ramp (Whole Number Only) | B11: 197
A12: Number of Garage Bays | B12: 4
A13: Spaces Passed in Up Circuit > Spaces Passed in Down Circuit? | B13: YES
A14: Stall Angle (Drop-Down List) | B14: 90° | E14: GEOMETRY
A15: Standard Parking Stall Width (Drop-Down List) | B15: 9'-0"
A16: Bay Width (Drop Down List) (Round Down to nearest choice) | B16: 61' | G16: Note:This row has a drop down list dependent on the stall angle. You MUST update this row after you change stall angle.
A17: End Bay Width (Decimal Feet) | B17: 32
A18: Circulation (One way / Two way) | B18: Two-Way
A19: Column at the end of the spaces? (Typical in short-span construction) | B19: NO
A20: Flat Floor Parking (%) | B20: 65 | E20: WAYFINDING
A21: Clear Height - 3'-0" Structure Assumed (Drop-Down List) | B21: 10'-6" (7'-6" CLR)
A22: Construction Type (Drop-Down List) | B22: Precast
A23: Counting System to be Installed in Garage? (Drop-Down List) | B23: None
A24: Ramp Aligned with Entry/Exit? (Yes/No) | B24: YES
A25: Contiguous Flat Floor Parking? (Yes/No) | B25: YES
A26: CIP : Cable Rails or Walls on Interior Ramp? | B26: Cable Rails
A27: Precast : Shear Wall Location - Exterior/Interior/End Bays? | B27: End Bays
A29: =B3 -> MDACC South Campus Garage 2
A30: Summary of Level of Service | B30: =B4 -> Option 1 | C30: =C4 -> Option 2 | D30: =D4 -> Option 3
A31: Overall Ramping Score | B31: =Ramping!B37 -> 86.670604 | C31: =Ramping!C37 -> #N/A | D31: =Ramping!D37 -> #N/A | E31: (See Tab for Detailed Information)
A32: Overall Geometry Score | B32: =Geometry!B33 -> 94.955 | C32: =Geometry!C33 -> 0.25 | D32: =Geometry!D33 -> 0.25 | E32: (See Tab for Detailed Information)
A33: Overall Wayfinding Score (w/Enhancements) | B33: =Wayfinding!B32 -> 83.436 | C33: =Wayfinding!C32 -> 0.4 | D33: =Wayfinding!D32 -> 0.4 | E33: (See Tab for Detailed Information)
A35: Final Weighted Level of Service
A36: Ramps (45%) | B36: =B31*0.45 -> 39.001772 | C36: =C31*0.45 -> #N/A | D36: =D31*0.45 -> #N/A
A37: Geometry (40%) | B37: =B32*0.4 -> 37.982 | C37: =C32*0.4 -> 0.1 | D37: =D32*0.4 -> 0.1
A38: Wayfinding (15%) | B38: =B33*0.15 -> 12.5154 | C38: =C33*0.15 -> 0.06 | D38: =D33*0.15 -> 0.06
A39: TOTAL SCORE | B39: =SUM(B36:B38) -> 89.499172 | C39: =SUM(C36:C38) -> #N/A | D39: =SUM(D36:D38) -> #N/A
A40: LOS LETTER GRADE | B40: =IF(OR(B31<70,B32<70),"Garage Fails - Check Ramping & Geometry",_xlfn.XLOOKUP(B39,Data!$B$70:$B$83,Data!$D$70:$D$83,,-1,1)) -> LOS B | C40: =IF(OR(C31<70,C32<70),"Garage Fails - Check Ramping & Geometry",_xlfn.XLOOKUP(C39,Data!$B$70:$B$83,Data!$D$70:$D$83,,-1,1)) -> #N/A | D40: =IF(OR(D31<70,D32<70),"Garage Fails - Check Ramping & Geometry",_xlfn.XLOOKUP(D39,Data!$B$70:$B$83,Data!$D$70:$D$83,,-1,1)) -> #N/A

Sheet Ramping
A1: Every Calculation is automatic. Do not manually manipulate any data on this sheet!
B2: =Summary!B3 -> MDACC South Campus Garage 2
B3: =Summary!B4 -> Option 1 | C3: =Summary!C4 -> Option 2 | D3: =Summary!D4 -> Option 3
A4: Parameter
A5: Market Sector | B5: =Summary!B5 -> Research | C5: =Summary!C5 -> 0 | D5: =Summary!D5 -> 0
A6: Space Count | B6: =Summary!B6 -> 1732 | C6: =Summary!C6 -> 0 | D6: =Summary!D6 -> 0
A7: Ramp Type | B7: =Summary!B8 -> Double Threaded Helix - 2 Way | C7: =Summary!C8 -> 0 | D7: =Summary!D8 -> 0
A8: Peak Load Factor (Percentage Expressed as Decimal) | B8: {=MAX(VLOOKUP(B5,Data!$A$12:$E$26,{2,3,4,5},0))} -> 0.55 | C8: {=MAX(VLOOKUP(C5,Data!$A$12:$E$26,{2,3,4,5},0))} -> #N/A | D8: {=MAX(VLOOKUP(D5,Data!$A$12:$E$26,{2,3,4,5},0))} -> #N/A
A9: Number of Spaces Not Engaged by Ramp | B9: =Summary!B11 -> 197 | C9: =Summary!C11 -> 0 | D9: =Summary!D11 -> 0
A10: Max Peak Load Per Hour | B10: =(B6*B8)-B9 -> 755.6 | C10: =(C6*C8)-C9 -> #N/A | D10: =(D6*D8)-D9 -> #N/A
A11: Number of Levels | B11: =Summary!B7 -> 7 | C11: =Summary!C7 -> 0 | D11: =Summary!D7 -> 0
A12: % of Ramp Capacity | B12: =B10/IFERROR(VLOOKUP(Summary!B8,Data!$A$37:$B$44,2,FALSE),"") -> 0.83955556 | C12: =C10/IFERROR(VLOOKUP(Summary!C8,Data!$A$37:$B$44,2,FALSE),"") -> #N/A | D12: =D10/IFERROR(VLOOKUP(Summary!D8,Data!$A$37:$B$44,2,FALSE),"") -> #N/A
A13: Ramping Usage LOS | B13: =_xlfn.XLOOKUP(B14,Data!$B$70:$B$83,Data!$D$70:$D$83,,-1,1) -> LOS C | C13: =_xlfn.XLOOKUP(C14,Data!$B$70:$B$83,Data!$D$70:$D$83,,-1,1) -> #N/A | D13: =_xlfn.XLOOKUP(D14,Data!$B$70:$B$83,Data!$D$70:$D$83,,-1,1) -> #N/A
A14: Numerical Score Equivalent | B14: =Data!B67 -> 79.851208 | C14: =Data!D67 -> #N/A | D14: =Data!F67 -> #N/A
A16: Parameter
A17: Number of 360 Degree Revolutions to Last Space | B17: =Summary!B10 -> 3.5 | C17: =Summary!C10 -> 0 | D17: =Summary!D10 -> 0
A18: Revolution LOS | B18: =_xlfn.XLOOKUP(B19,Data!$B$70:$B$83,Data!$D$70:$D$83,,-1,1) -> LOS A- | C18: =_xlfn.XLOOKUP(C19,Data!$B$70:$B$83,Data!$D$70:$D$83,,-1,1) -> #N/A | D18: =_xlfn.XLOOKUP(D19,Data!$B$70:$B$83,Data!$D$70:$D$83,,-1,1) -> #N/A
A19: Numerical Score Equivalent (use Midpoint of LOS) | B19: =Data!A93 -> 93 | C19: =Data!C93 -> #N/A | D19: =Data!E93 -> #N/A
A21: Parameter
A22: Ramp Slope (TYP Floor) In PERCENT | B22: =Summary!B9 -> 4.86 | C22: =Summary!C9 -> 0 | D22: =Summary!D9 -> 0
A23: Ramp Slope LOS | B23: =IF(ISERROR(SEARCH("Express Ramp",Ramping!B7))*AND(B22>6.67),"Recommend Express Ramp", IF(ISNUMBER(SEARCH("Express Ramp",Ramping!B7))*AND(B22<6.67),"Recommend Park-On-Ramp", _xlfn.XLOOKUP(B24,Data!$B$70:$B$83,Data!$D$70:$D$83,,-1,1))) -> LOS A- | C23: =IF(ISERROR(SEARCH("Express Ramp",Ramping!C7))*AND(C22>6.67),"Recommend Express Ramp", IF(ISNUMBER(SEARCH("Express Ramp",Ramping!C7))*AND(C22<6.67),"Recommend Park-On-Ramp", _xlfn.XLOOKUP(C24,Data!$B$70:$B$83,Data!$D$70:$D$83,,-1,1))) -> #N/A | D23: =IF(ISERROR(SEARCH("Express Ramp",Ramping!D7))*AND(D22>6.67),"Recommend Express Ramp", IF(ISNUMBER(SEARCH("Express Ramp",Ramping!D7))*AND(D22<6.67),"Recommend Park-On-Ramp", _xlfn.XLOOKUP(D24,Data!$B$70:$B$83,Data!$D$70:$D$83,,-1,1))) -> #N/A
A24: Numerical Score Equivalent | B24: =Data!A129 -> 93.98 | C24: =Data!C129 -> #N/A | D24: =Data!E129 -> #N/A
A27: Ramping System Weighted Level of Service
A28: Ramp Capacity (50%) | B28: =B14*0.5 -> 39.925604 | C28: =C14*0.5 -> #N/A | D28: =D14*0.5 -> #N/A
A29: Turns to the top (25%) | B29: =B19*0.25 -> 23.25 | C29: =C19*0.25 -> #N/A | D29: =D19*0.25 -> #N/A
A30: Ramp Slope (25%) | B30: =B24*0.25 -> 23.495 | C30: =C24*0.25 -> #N/A | D30: =D24*0.25 -> #N/A
A31: Numerical Score Equivalent | B31: =SUM(B28:B30) -> 86.670604 | C31: =SUM(C28:C30) -> #N/A | D31: =SUM(D28:D30) -> #N/A
A33: Ramping Enhancement/Reduction
A34: Up Circuit is Greater than Down Circuit? (N=-7%) | B34: =IF(Summary!B13="NO",-7%, "None") -> None | C34: =IF(Summary!C13="NO",-7%, "None") -> None | D34: =IF(Summary!D13="NO",-7%, "None") -> None | E34: Impact is also seen in Wayfinding Category. See TAB.
A35: Total Ramping Enhancement/Reduction Percentage | B35: =SUM(B34) -> 0 | C35: =SUM(C34) -> 0 | D35: =SUM(D34) -> 0
A37: TOTAL Ramping Level Of Service Score | B37: =B31*(1+B35) -> 86.670604 | C37: =C31*(1+C35) -> #N/A | D37: =D31*(1+D35) -> #N/A
A38: Overall Ramping Level of Service Grade | B38: =_xlfn.XLOOKUP(B37,Data!$B$70:$B$83,Data!$D$70:$D$83,,-1,1) -> LOS B | C38: =_xlfn.XLOOKUP(C37,Data!$B$70:$B$83,Data!$D$70:$D$83,,-1,1) -> #N/A | D38: =_xlfn.XLOOKUP(D37,Data!$B$70:$B$83,Data!$D$70:$D$83,,-1,1) -> #N/A

Sheet Geometry
A1: Every Calculation is automatic. Do not manually manipulate any data on this sheet!
B2: =Summary!B3 -> MDACC South Campus Garage 2
A3: Parameter | B3: =Summary!B4 -> Option 1 | C3: =Summary!C4 -> Option 2 | D3: =Summary!D4 -> Option 3
A5: Stall Angle | B5: =Summary!B14 -> 90° | C5: =Summary!C14 -> 0 | D5: =Summary!D14 -> 0
A6: Bay Width (Decimal Feet) | B6: =Summary!B16 -> 61' | C6: =Summary!C16 -> 0 | D6: =Summary!D16 -> 0
A7: Bay Width LOS | B7: {=IFERROR(INDEX(Data!$I$116:$L$116,,MATCH(Geometry!B6,INDEX(Data!$I$117:$L$124,MATCH(Geometry!B5,Data!$H$117:$H$124,0),),0)),"Bay Width Not Appropriate for Stall Angle")} -> LOS B | C7: {=IFERROR(INDEX(Data!$I$116:$L$116,,MATCH(Geometry!C6,INDEX(Data!$I$117:$L$124,MATCH(Geometry!C5,Data!$H$117:$H$124,0),),0)),"Bay Width Not Appropriate for Stall Angle")} -> Bay Width Not Appropriate for Stall Angle | D7: {=IFERROR(INDEX(Data!$I$116:$L$116,,MATCH(Geometry!D6,INDEX(Data!$I$117:$L$124,MATCH(Geometry!D5,Data!$H$117:$H$124,0),),0)),"Bay Width Not Appropriate for Stall Angle")} -> Bay Width Not Appropriate for Stall Angle
A8: Numerical Score Equivelant (use Midpoint of LOS) | B8: =IF(B7="LOS A",Data!$C$70,IF(Geometry!B7="LOS B",Data!$C$73,IF(Geometry!B7="LOS C",Data!$C$76,IF(Geometry!B7="LOS D",Data!$C$79,IF(Geometry!B7="LOS F",Data!$C$82))))) -> 92.9 | C8: =IF(C7="LOS A",Data!$C$70,IF(Geometry!C7="LOS B",Data!$C$73,IF(Geometry!C7="LOS C",Data!$C$76,IF(Geometry!C7="LOS D",Data!$C$79,IF(Geometry!C7="LOS F",Data!$C$82))))) -> FALSE | D8: =IF(D7="LOS A",Data!$C$70,IF(Geometry!D7="LOS B",Data!$C$73,IF(Geometry!D7="LOS C",Data!$C$76,IF(Geometry!D7="LOS D",Data!$C$79,IF(Geometry!D7="LOS F",Data!$C$82))))) -> FALSE
A10: Parameter
A11: Circulation (One-Way/Two-Way) | B11: =Summary!B18 -> Two-Way | C11: =Summary!C18 -> 0 | D11: =Summary!D18 -> 0
A12: End Bay Dimension (Decimal Feet) | B12: =Summary!B17 -> 32 | C12: =Summary!C17 -> 0 | D12: =Summary!D17 -> 0
A13: End Bay LOS | B13: =_xlfn.XLOOKUP(B14,Data!$B$70:$B$83,Data!$D$70:$D$83,,-1,1) -> LOS A | C13: =_xlfn.XLOOKUP(C14,Data!$B$70:$B$83,Data!$D$70:$D$83,,-1,1) -> F Not Recommended | D13: =_xlfn.XLOOKUP(D14,Data!$B$70:$B$83,Data!$D$70:$D$83,,-1,1) -> F Not Recommended
A14: Numerical Score Equivelant | B14: =Data!A200 -> 94.6 | C14: =Data!C200 -> 0 | D14: =Data!E200 -> 0
A16: Parameter
A17: Standard Size Parking Stall Size (Feet) | B17: =Summary!B15 -> 9'-0" | C17: =Summary!C15 -> 0 | D17: =Summary!D15 -> 0
A18: Parking Stall LOS | B18: =_xlfn.XLOOKUP(B17,Data!$B$133:$B$156,Data!$D$133:$D$156,1) -> LOS A | C18: =_xlfn.XLOOKUP(C17,Data!$B$133:$B$156,Data!$D$133:$D$156,1) -> 1 | D18: =_xlfn.XLOOKUP(D17,Data!$B$133:$B$156,Data!$D$133:$D$156,1) -> 1
A19: Numerical Score Equivelant | B19: =_xlfn.XLOOKUP(B17,Data!$B$133:$B$156,Data!$C$133:$C$156,1) -> 98.4 | C19: =_xlfn.XLOOKUP(C17,Data!$B$133:$B$156,Data!$C$133:$C$156,1) -> 1 | D19: =_xlfn.XLOOKUP(D17,Data!$B$133:$B$156,Data!$C$133:$C$156,1) -> 1
A21: Geometry Weighted Level Of Service
A22: Bay Width (35%) | B22: =B8*0.35 -> 32.515 | C22: =C8*0.35 -> 0 | D22: =D8*0.35 -> 0
A23: End Bay Dimension (40%) | B23: =B14*0.4 -> 37.84 | C23: =C14*0.4 -> 0 | D23: =D14*0.4 -> 0
A24: Parking Stall Size (25%) | B24: =B19*0.25 -> 24.6 | C24: =C19*0.25 -> 0.25 | D24: =D19*0.25 -> 0.25
A26: Baseline Geometry Level Of Service Score | B26: =SUM(B22:B24) -> 94.955 | C26: =SUM(C22:C24) -> 0.25 | D26: =SUM(D22:D24) -> 0.25
A27: Baseline Geometry Level of Service Grade | B27: =_xlfn.XLOOKUP(B26,Data!$B$70:$B$83,Data!$D$70:$D$83,,-1,1) -> LOS A | C27: =_xlfn.XLOOKUP(C26,Data!$B$70:$B$83,Data!$D$70:$D$83,,-1,1) -> F Not Recommended | D27: =_xlfn.XLOOKUP(D26,Data!$B$70:$B$83,Data!$D$70:$D$83,,-1,1) -> F Not Recommended
A29: Geometry Enhancement/Reduction
A30: Column at the end of the space (Short Span) - Usually present in podiumn garages (3%) | B30: =IF(Summary!B19="YES",-3%, "None") -> None | C30: =IF(Summary!C19="YES",-3%, "None") -> None | D30: =IF(Summary!D19="YES",-3%, "None") -> None
A31: Total Geometry Enhancement/Reduction | B31: =SUM(B30) -> 0 | C31: =SUM(C30) -> 0 | D31: =SUM(D30) -> 0
A33: Total Geometry Level of Service Score with Enhancements | B33: =IF((B26+B26*B31)>100,100,(B26+B26*B31)) -> 94.955 | C33: =IF((C26+C26*C31)>100,100,(C26+C26*C31)) -> 0.25 | D33: =IF((D26+D26*D31)>100,100,(D26+D26*D31)) -> 0.25
A34: Overall Geometry Level of Service Grade with Enhancements | B34: =_xlfn.XLOOKUP(B33,Data!$B$70:$B$83,Data!$D$70:$D$83,,-1,1) -> LOS A | C34: =_xlfn.XLOOKUP(C33,Data!$B$70:$B$83,Data!$D$70:$D$83,,-1,1) -> F Not Recommended | D34: =_xlfn.XLOOKUP(D33,Data!$B$70:$B$83,Data!$D$70:$D$83,,-1,1) -> F Not Recommended

Sheet Wayfinding
A1: Every Calculation is automatic. Do not manually manipulate any data on this sheet!
A2: Parameter | B2: =Summary!B4 -> Option 1 | C2: =Summary!C4 -> Option 2 | D2: =Summary!D4 -> Option 3
A4: Flat Floor Parking (%) | B4: =Summary!B20 -> 65 | C4: =Summary!C20 -> 0 | D4: =Summary!D20 -> 0
A5: Percent Flat Floor Parking LOS | B5: =_xlfn.XLOOKUP(B6,Data!$B$70:$B$83,Data!$D$70:$D$83,,-1,1) -> LOS B- | C5: =_xlfn.XLOOKUP(C6,Data!$B$70:$B$83,Data!$D$70:$D$83,,-1,1) -> F Not Recommended | D5: =_xlfn.XLOOKUP(D6,Data!$B$70:$B$83,Data!$D$70:$D$83,,-1,1) -> F Not Recommended
A6: Numerical Score Equivalent | B6: =Data!A222 -> 85 | C6: =Data!C222 -> 0 | D6: =Data!E222 -> 0
A8: Parameter
A9: Typical Floor to Floor Height (Clear) | B9: =Summary!B21 -> 10'-6" (7'-6" CLR) | C9: =Summary!C21 -> 0 | D9: =Summary!D21 -> 0
A10: Typical Floor to Floor Height LOS | B10: =_xlfn.XLOOKUP(B11,Data!$C$226:$C$250,Data!$D$226:$D$250,1) -> C | C10: =_xlfn.XLOOKUP(C11,Data!$C$226:$C$250,Data!$D$226:$D$250,1) -> 1 | D10: =_xlfn.XLOOKUP(D11,Data!$C$226:$C$250,Data!$D$226:$D$250,1) -> 1
A11: Numerical Score Equivalent (use Midpoint of LOS) | B11: =_xlfn.XLOOKUP(B9,Data!$B$226:$B$250,Data!$C$226:$C$250,1) -> 77 | C11: =_xlfn.XLOOKUP(C9,Data!$B$226:$B$250,Data!$C$226:$C$250,1) -> 1 | D11: =_xlfn.XLOOKUP(D9,Data!$B$226:$B$250,Data!$C$226:$C$250,1) -> 1
A13: Wayfinding Weighted Level Of Service
A14: Percent Flat Floor Parking (60%) | B14: =B6*0.6 -> 51 | C14: =C6*0.6 -> 0 | D14: =D6*0.6 -> 0
A15: Floor to Floor Height (40%) | B15: =B11*0.4 -> 30.8 | C15: =C11*0.4 -> 0.4 | D15: =D11*0.4 -> 0.4
A16: Baseline Wayfinding Level Of Service Score | B16: =SUM(B14:B15) -> 81.8 | C16: =SUM(C14:C15) -> 0.4 | D16: =SUM(D14:D15) -> 0.4
A17: Baseline Wayfinding Level of Service Grade | B17: =_xlfn.XLOOKUP(B16,Data!$B$70:$B$83,Data!$D$70:$D$83,,-1,1) -> LOS C | C17: =_xlfn.XLOOKUP(C16,Data!$B$70:$B$83,Data!$D$70:$D$83,,-1,1) -> F Not Recommended | D17: =_xlfn.XLOOKUP(D16,Data!$B$70:$B$83,Data!$D$70:$D$83,,-1,1) -> F Not Recommended
A19: Wayfinding Score Enhancements/Reductions
A20: Single Space Detection System? (5%) | B20: =IF(Summary!$B$23= "Single Space Detection System", 5%,"None") -> None | C20: =IF(Summary!$C$23= "Single Space Detection System", 5%,"None") -> None | D20: =IF(Summary!$D$23= "Single Space Detection System", 5%,"None") -> None
A21: Level Count System? (3%) | B21: =IF(Summary!$B$23= "Level Count System",3%,"None") -> None | C21: =IF(Summary!$C$23= "Level Count System",3%,"None") -> None | D21: =IF(Summary!$D$23= "Level Count System",3%,"None") -> None
A22: Facility Count System? (2%) | B22: =IF(Summary!$B$23= "Facility Count System", 2%,"None") -> None | C22: =IF(Summary!$C$23= "Facility Count System", 2%,"None") -> None | D22: =IF(Summary!$D$23= "Facility Count System",2%,"None") -> None
A23: Ramp Aligned with Entry/Exit (1%) | B23: =IF(Summary!B24="YES",1%, "None") -> 0.01 | C23: =IF(Summary!C24="YES",1%, "None") -> None | D23: =IF(Summary!D24="YES",1%, "None") -> None
A24: Contiguous Flat Floor Parking? Both CIP & Precast (3%) | B24: =IF(Summary!B25="YES",3%, "None") -> 0.03 | C24: =IF(Summary!C25="YES",3%, "None") -> None | D24: =IF(Summary!D25="YES",3%, "None") -> None
A25: Precast/CIP | B25: =Summary!B22 -> Precast | C25: =Summary!C22 -> 0 | D25: =Summary!D22 -> 0
A26: CIP : Cable Rails (+1%) or Walls (0%)? | B26: =IF(B25="Precast","None",IF(Summary!B26="Cable Rails",1%,IF(Summary!B26="Walls",0%,"None"))) -> None | C26: =IF(C25="Precast","None",IF(Summary!C26="Cable Rails",1%,IF(Summary!C26="Walls",0%,"None"))) -> None | D26: =IF(D25="Precast","None",IF(Summary!D26="Cable Rails",1%,IF(Summary!D26="Walls",0%,"None"))) -> None
A27: Precast : Shear Wall Location - Exterior(+1%)/Interior(-1%)/End Bays(-2%)? | B27: =IF(B25="Cast-In-Place","None",IF(Summary!B27="Not Precast","None",IF(Summary!B27="Exterior",1%,IF(Summary!B27="Interior",-1%,IF(Summary!B27="End Bays",-2%))))) -> -0.02 | C27: =IF(C25="Cast-In-Place","None",IF(Summary!C27="Not Precast","None",IF(Summary!C27="Exterior",1%,IF(Summary!C27="Interior",-1%,IF(Summary!C27="End Bays",-2%))))) -> FALSE | D27: =IF(D25="Cast-In-Place","None",IF(Summary!D27="Not Precast","None",IF(Summary!D27="Exterior",1%,IF(Summary!D27="Interior",-1%,IF(Summary!D27="End Bays",-2%))))) -> FALSE
A28: Lighting Levels | E28: TBD | F28: LOS Scale on Lighting
A29: Up Circuit is Greater than Down Circuit? (N=-7%) | B29: =IF(Summary!B13="NO",-7%, "None") -> None | C29: =IF(Summary!C13="NO",-7%, "None") -> None | D29: =IF(Summary!D13="NO",-7%, "None") -> None
A30: Total Wayfinding Enhancement/Reduction Percentage | B30: =SUM(B20:B29) -> 0.02 | C30: =SUM(C20:C29) -> 0 | D30: =SUM(D20:D29) -> 0
A32: Total Wayfinding Level of Service Score with Enhancements | B32: =IF((B16+B16*B30)>100,100,(B16+B16*B30)) -> 83.436 | C32: =IF((C16+C16*C30)>100,100,(C16+C16*C30)) -> 0.4 | D32: =IF((D16+D16*D30)>100,100,(D16+D16*D30)) -> 0.4
A33: Overall Wayfinding Level of Service Grade with Enhancements | B33: =_xlfn.XLOOKUP(B32,Data!$B$70:$B$83,Data!$D$70:$D$83,,-1,1) -> LOS C+ | C33: =_xlfn.XLOOKUP(C32,Data!$B$70:$B$83,Data!$D$70:$D$83,,-1,1) -> F Not Recommended | D33: =_xlfn.XLOOKUP(D32,Data!$B$70:$B$83,Data!$D$70:$D$83,,-1,1) -> F Not Recommended

Sheet Data
A2: Criteria | B2: LOS
A3: Poor (Not Recommended) | B3: F
A4: Fair | B4: D
A5: Acceptable | B5: C
A6: Good | B6: B
A7: Excellent | B7: A
A9: Peak Load Factor
A10: Peak Load Factor by Use Type | B10: Peak AM | D10: Peak PM
B11: In | C11: Out | D11: In | E11: Out
A12: Residential | B12: 0.05 | C12: 0.4 | D12: 0.4 | E12: 0.2
A13: Hotel | B13: 0.35 | C13: 0.5 | D13: 0.4 | E13: 0.35
A14: Office | B14: 0.5 | C14: 0.05 | D14: 0.1 | E14: 0.5
A15: Retail | B15: 0.3 | C15: 0.4 | D15: 0.5 | E15: 0.5
A16: Restaurant | B16: 0.35 | C16: 0.35 | D16: 0.5 | E16: 0.4
A17: Cinema | B17: 0.5 | C17: 0.3 | D17: 0.25 | E17: 0.6
A18: Special Event | B18: 0.9 | C18: 0.05 | D18: 0.05 | E18: 1
A19: Research | B19: 0.55 | C19: 0.05 | D19: 0.1 | E19: 0.55
A20: Hospital Visitor | B20: 0.4 | C20: 0.4 | D20: 0.4 | E20: 0.4
A21: Hospital Employee | B21: 0.6 | C21: 0.1 | D21: 0.1 | E21: 0.6
A22: Hospital Outpatient | B22: 0.7 | C22: 0.05 | D22: 0.25 | E22: 0.7
A23: Hospital Mixed | B23: =(((B20*100)*Summary!$H$6)+((Data!B21*100)*Summary!$H$7)+((Data!B22*100)*Summary!$H$8))/100 -> 0.6 | C23: =(((C20*100)*Summary!$H$6)+((Data!C21*100)*Summary!$H$7)+((Data!C22*100)*Summary!$H$8))/100 -> 0.15 | D23: =(((D20*100)*Summary!$H$6)+((Data!D21*100)*Summary!$H$7)+((Data!D22*100)*Summary!$H$8))/100 -> 0.25 | E23: =(((E20*100)*Summary!$H$6)+((Data!E21*100)*Summary!$H$7)+((Data!E22*100)*Summary!$H$8))/100 -> 0.6 | F23: WEIGHTED FORMULA
A24: University Students | B24: 0.33 | C24: 0.33 | D24: 0.33 | E24: 0.33
A25: University Staff | B25: 0.5 | C25: 0.05 | D25: 0.1 | E25: 0.5
A26: University Faculty | B26: 0.4 | C26: 0.2 | D26: 0.1 | E26: 0.4
A27: University Mixed | B27: =(((Data!B24*100)*Summary!$K$6)+((Data!B25*100)*Summary!$K$7)+((Data!B26*100)*Summary!$K$8))/100 -> 0.45 | C27: =(((Data!C24*100)*Summary!$K$6)+((Data!C25*100)*Summary!$K$7)+((Data!C26*100)*Summary!$K$8))/100 -> 0.125 | D27: =(((Data!D24*100)*Summary!$K$6)+((Data!D25*100)*Summary!$K$7)+((Data!D26*100)*Summary!$K$8))/100 -> 0.1 | E27: =(((Data!E24*100)*Summary!$K$6)+((Data!E25*100)*Summary!$K$7)+((Data!E26*100)*Summary!$K$8))/100 -> 0.45 | F27: WEIGHTED FORMULA
A28: Mixed Use | B28: Fill In (Situational) | C28: Fill In Manually | D28: Fill In Manually | E28: Fill In Manually | F28: WEIGHTED FORMULA
A31: Percent of Maximum Capacity
C32: 100%+ | D32: 90%-99% | E32: 75% to 89% | F32: 60%-75% | G32: <59%
B33: Midpoint of Range | C33: 100 | D33: =(90+99)/2 -> 94.5 | E33: =(75+89)/2 -> 82 | F33: =(60+75)/2 -> 67.5
C34: Poor | D34: Fair | E34: Acceptable | F34: Good | G34: Excellent
B35: LOS | C35: F | D35: D | E35: C | F35: B | G35: A
A36: Ramp Type | B36: Max Capacity (vph)
A37: Single Threaded Helix - 2 Way | B37: 450 | C37: >450 | D37: 405 to 450 | E37: 340 to 405 | F37: 270 to 340 | G37: <270
A38: Double Threaded Helix - 1 Way | B38: 800 | C38: >800 | D38: 720 to 800 | E38: 600 to 720 | F38: 480 to 600 | G38: <480
A39: Double Threaded Helix - 2 Way | B39: 900 | C39: >900 | D39: 810 to 900 | E39: 675 to 810 | F39: 540 to 675 | G39: <540
A40: Express Ramp Straight | B40: 1000 | C40: >1000 | D40: 900 to 1000 | E40: 750 to 900 | F40: 600 to 750 | G40: <600
A41: Cascading Express Ramp (2 Fl Cut) | B41: =B40*1.5 -> 1500 | C41: >1500 | D41: 1,350 to 1,500 | E41: 1,125 to 1,350 | F41: 900 to 1,125 | G41: <900
A42: Cascading Express Ramp (3 Fl Cut) | B42: =B41*1.5 -> 2250 | C42: >2250 | D42: 2,025 to 2,250 | E42: 1,690 to 2,025 | F42: 1,350 to 1,690 | G42: <1,350
A43: Cascading Stacked Express Ramp (2 Fl Cut) | B43: 2000 | C43: >2000 | D43: 1,800 to 2,000 | E43: 1,500 to 1,800 | F43: 1,200 to 1,500 | G43: <1,200
A44: Express Ramp Circular | B44: 900 | C44: >900 | D44: 810 to 900 | E44: 675 to 810 | F44: 540 to 675 | G44: <540
...
